[2021-01-14 11:07:57,073] {taskinstance.py:670} INFO - Dependencies all met for <TaskInstance: test_daily_0030.check_monthly 2021-01-13T00:30:00+00:00 [queued]>
[2021-01-14 11:07:57,088] {taskinstance.py:670} INFO - Dependencies all met for <TaskInstance: test_daily_0030.check_monthly 2021-01-13T00:30:00+00:00 [queued]>
[2021-01-14 11:07:57,088] {taskinstance.py:880} INFO - 
--------------------------------------------------------------------------------
[2021-01-14 11:07:57,088] {taskinstance.py:881} INFO - Starting attempt 2 of 5
[2021-01-14 11:07:57,088] {taskinstance.py:882} INFO - 
--------------------------------------------------------------------------------
[2021-01-14 11:07:57,093] {taskinstance.py:901} INFO - Executing <Task(ShortCircuitOperator): check_monthly> on 2021-01-13T00:30:00+00:00
[2021-01-14 11:07:57,097] {standard_task_runner.py:54} INFO - Started process 12887 to run task
[2021-01-14 11:07:57,117] {standard_task_runner.py:77} INFO - Running: ['airflow', 'run', 'test_daily_0030', 'check_monthly', '2021-01-13T00:30:00+00:00', '--job_id', '21', '--pool', 'default_pool', '--raw', '-sd', 'DAGS_FOLDER/test_daily_0030.py', '--cfg_path', '/var/folders/1c/xhkpty0142l7xwkrqtm3t9p80000gn/T/tmpuv49az88']
[2021-01-14 11:07:57,118] {standard_task_runner.py:78} INFO - Job 21: Subtask check_monthly
[2021-01-14 11:07:57,149] {logging_mixin.py:112} INFO - Running %s on host %s <TaskInstance: test_daily_0030.check_monthly 2021-01-13T00:30:00+00:00 [running]> iwonjiui-macbookpro.local
[2021-01-14 11:07:57,163] {taskinstance.py:1150} ERROR - check_monthly() got an unexpected keyword argument 'conf'
Traceback (most recent call last):
  File "/Users/wonji/.pyenv/versions/3.7.7/envs/test_airflow/lib/python3.7/site-packages/airflow/models/taskinstance.py", line 984, in _run_raw_task
    result = task_copy.execute(context=context)
  File "/Users/wonji/.pyenv/versions/3.7.7/envs/test_airflow/lib/python3.7/site-packages/airflow/operators/python_operator.py", line 158, in execute
    condition = super(ShortCircuitOperator, self).execute(context)
  File "/Users/wonji/.pyenv/versions/3.7.7/envs/test_airflow/lib/python3.7/site-packages/airflow/operators/python_operator.py", line 113, in execute
    return_value = self.execute_callable()
  File "/Users/wonji/.pyenv/versions/3.7.7/envs/test_airflow/lib/python3.7/site-packages/airflow/operators/python_operator.py", line 118, in execute_callable
    return self.python_callable(*self.op_args, **self.op_kwargs)
TypeError: check_monthly() got an unexpected keyword argument 'conf'
[2021-01-14 11:07:57,164] {taskinstance.py:1194} INFO - Marking task as UP_FOR_RETRY. dag_id=test_daily_0030, task_id=check_monthly, execution_date=20210113T003000, start_date=20210114T020757, end_date=20210114T020757
[2021-01-14 11:07:57,175] {configuration.py:373} WARNING - section/key [smtp/smtp_user] not found in config
[2021-01-14 11:07:57,178] {configuration.py:373} WARNING - section/key [smtp/smtp_user] not found in config
[2021-01-14 11:07:57,179] {taskinstance.py:1200} ERROR - Failed to send email to: ['wonji']
[2021-01-14 11:07:57,179] {taskinstance.py:1201} ERROR - [Errno 61] Connection refused
Traceback (most recent call last):
  File "/Users/wonji/.pyenv/versions/3.7.7/envs/test_airflow/lib/python3.7/site-packages/airflow/models/taskinstance.py", line 984, in _run_raw_task
    result = task_copy.execute(context=context)
  File "/Users/wonji/.pyenv/versions/3.7.7/envs/test_airflow/lib/python3.7/site-packages/airflow/operators/python_operator.py", line 158, in execute
    condition = super(ShortCircuitOperator, self).execute(context)
  File "/Users/wonji/.pyenv/versions/3.7.7/envs/test_airflow/lib/python3.7/site-packages/airflow/operators/python_operator.py", line 113, in execute
    return_value = self.execute_callable()
  File "/Users/wonji/.pyenv/versions/3.7.7/envs/test_airflow/lib/python3.7/site-packages/airflow/operators/python_operator.py", line 118, in execute_callable
    return self.python_callable(*self.op_args, **self.op_kwargs)
TypeError: check_monthly() got an unexpected keyword argument 'conf'

During handling of the above exception, another exception occurred:

Traceback (most recent call last):
  File "/Users/wonji/.pyenv/versions/3.7.7/envs/test_airflow/lib/python3.7/site-packages/airflow/models/taskinstance.py", line 1473, in email_alert
    send_email(self.task.email, subject, html_content)
  File "/Users/wonji/.pyenv/versions/3.7.7/envs/test_airflow/lib/python3.7/site-packages/airflow/utils/email.py", line 62, in send_email
    mime_subtype=mime_subtype, mime_charset=mime_charset, **kwargs)
  File "/Users/wonji/.pyenv/versions/3.7.7/envs/test_airflow/lib/python3.7/site-packages/airflow/utils/email.py", line 108, in send_email_smtp
    send_MIME_email(smtp_mail_from, recipients, msg, dryrun)
  File "/Users/wonji/.pyenv/versions/3.7.7/envs/test_airflow/lib/python3.7/site-packages/airflow/utils/email.py", line 127, in send_MIME_email
    s = smtplib.SMTP_SSL(SMTP_HOST, SMTP_PORT) if SMTP_SSL else smtplib.SMTP(SMTP_HOST, SMTP_PORT)
  File "/Users/wonji/.pyenv/versions/3.7.7/lib/python3.7/smtplib.py", line 251, in __init__
    (code, msg) = self.connect(host, port)
  File "/Users/wonji/.pyenv/versions/3.7.7/lib/python3.7/smtplib.py", line 336, in connect
    self.sock = self._get_socket(host, port, self.timeout)
  File "/Users/wonji/.pyenv/versions/3.7.7/lib/python3.7/smtplib.py", line 307, in _get_socket
    self.source_address)
  File "/Users/wonji/.pyenv/versions/3.7.7/lib/python3.7/socket.py", line 728, in create_connection
    raise err
  File "/Users/wonji/.pyenv/versions/3.7.7/lib/python3.7/socket.py", line 716, in create_connection
    sock.connect(sa)
ConnectionRefusedError: [Errno 61] Connection refused

During handling of the above exception, another exception occurred:

Traceback (most recent call last):
  File "/Users/wonji/.pyenv/versions/3.7.7/envs/test_airflow/lib/python3.7/site-packages/airflow/models/taskinstance.py", line 1198, in handle_failure
    self.email_alert(error)
  File "/Users/wonji/.pyenv/versions/3.7.7/envs/test_airflow/lib/python3.7/site-packages/airflow/models/taskinstance.py", line 1475, in email_alert
    send_email(self.task.email, subject, html_content_err)
  File "/Users/wonji/.pyenv/versions/3.7.7/envs/test_airflow/lib/python3.7/site-packages/airflow/utils/email.py", line 62, in send_email
    mime_subtype=mime_subtype, mime_charset=mime_charset, **kwargs)
  File "/Users/wonji/.pyenv/versions/3.7.7/envs/test_airflow/lib/python3.7/site-packages/airflow/utils/email.py", line 108, in send_email_smtp
    send_MIME_email(smtp_mail_from, recipients, msg, dryrun)
  File "/Users/wonji/.pyenv/versions/3.7.7/envs/test_airflow/lib/python3.7/site-packages/airflow/utils/email.py", line 127, in send_MIME_email
    s = smtplib.SMTP_SSL(SMTP_HOST, SMTP_PORT) if SMTP_SSL else smtplib.SMTP(SMTP_HOST, SMTP_PORT)
  File "/Users/wonji/.pyenv/versions/3.7.7/lib/python3.7/smtplib.py", line 251, in __init__
    (code, msg) = self.connect(host, port)
  File "/Users/wonji/.pyenv/versions/3.7.7/lib/python3.7/smtplib.py", line 336, in connect
    self.sock = self._get_socket(host, port, self.timeout)
  File "/Users/wonji/.pyenv/versions/3.7.7/lib/python3.7/smtplib.py", line 307, in _get_socket
    self.source_address)
  File "/Users/wonji/.pyenv/versions/3.7.7/lib/python3.7/socket.py", line 728, in create_connection
    raise err
  File "/Users/wonji/.pyenv/versions/3.7.7/lib/python3.7/socket.py", line 716, in create_connection
    sock.connect(sa)
ConnectionRefusedError: [Errno 61] Connection refused
[2021-01-14 11:08:02,271] {local_task_job.py:102} INFO - Task exited with return code 1
[2021-01-14 13:28:14,109] {taskinstance.py:670} INFO - Dependencies all met for <TaskInstance: test_daily_0030.check_monthly 2021-01-13T00:30:00+00:00 [queued]>
[2021-01-14 13:28:14,124] {taskinstance.py:670} INFO - Dependencies all met for <TaskInstance: test_daily_0030.check_monthly 2021-01-13T00:30:00+00:00 [queued]>
[2021-01-14 13:28:14,124] {taskinstance.py:880} INFO - 
--------------------------------------------------------------------------------
[2021-01-14 13:28:14,124] {taskinstance.py:881} INFO - Starting attempt 2 of 4
[2021-01-14 13:28:14,124] {taskinstance.py:882} INFO - 
--------------------------------------------------------------------------------
[2021-01-14 13:28:14,129] {taskinstance.py:901} INFO - Executing <Task(BranchPythonOperator): check_monthly> on 2021-01-13T00:30:00+00:00
[2021-01-14 13:28:14,133] {standard_task_runner.py:54} INFO - Started process 26984 to run task
[2021-01-14 13:28:14,153] {standard_task_runner.py:77} INFO - Running: ['airflow', 'run', 'test_daily_0030', 'check_monthly', '2021-01-13T00:30:00+00:00', '--job_id', '45', '--pool', 'default_pool', '--raw', '-sd', 'DAGS_FOLDER/test_daily_0030.py', '--cfg_path', '/var/folders/1c/xhkpty0142l7xwkrqtm3t9p80000gn/T/tmpmhiyww0l']
[2021-01-14 13:28:14,154] {standard_task_runner.py:78} INFO - Job 45: Subtask check_monthly
[2021-01-14 13:28:14,185] {logging_mixin.py:112} INFO - Running %s on host %s <TaskInstance: test_daily_0030.check_monthly 2021-01-13T00:30:00+00:00 [running]> 1.0.0.127.in-addr.arpa
[2021-01-14 13:28:14,204] {python_operator.py:114} INFO - Done. Returned value was: mid
[2021-01-14 13:28:14,205] {skipmixin.py:123} INFO - Following branch mid
[2021-01-14 13:28:14,207] {skipmixin.py:149} INFO - Skipping tasks ['wait_monthly']
[2021-01-14 13:28:14,217] {taskinstance.py:1070} INFO - Marking task as SUCCESS.dag_id=test_daily_0030, task_id=check_monthly, execution_date=20210113T003000, start_date=20210114T042814, end_date=20210114T042814
[2021-01-14 13:28:19,106] {local_task_job.py:102} INFO - Task exited with return code 0
