[2021-01-14 11:51:15,899] {taskinstance.py:670} INFO - Dependencies all met for <TaskInstance: test_daily_0030.wait_weekly 2021-01-13T00:30:00+00:00 [queued]>
[2021-01-14 11:51:15,918] {taskinstance.py:670} INFO - Dependencies all met for <TaskInstance: test_daily_0030.wait_weekly 2021-01-13T00:30:00+00:00 [queued]>
[2021-01-14 11:51:15,918] {taskinstance.py:880} INFO - 
--------------------------------------------------------------------------------
[2021-01-14 11:51:15,918] {taskinstance.py:881} INFO - Starting attempt 4 of 5
[2021-01-14 11:51:15,918] {taskinstance.py:882} INFO - 
--------------------------------------------------------------------------------
[2021-01-14 11:51:15,923] {taskinstance.py:901} INFO - Executing <Task(ExternalTaskSensor): wait_weekly> on 2021-01-13T00:30:00+00:00
[2021-01-14 11:51:15,927] {standard_task_runner.py:54} INFO - Started process 17399 to run task
[2021-01-14 11:51:15,949] {standard_task_runner.py:77} INFO - Running: ['airflow', 'run', 'test_daily_0030', 'wait_weekly', '2021-01-13T00:30:00+00:00', '--job_id', '48', '--pool', 'default_pool', '--raw', '-sd', 'DAGS_FOLDER/test_daily_0030.py', '--cfg_path', '/var/folders/1c/xhkpty0142l7xwkrqtm3t9p80000gn/T/tmpaxw_b_30']
[2021-01-14 11:51:15,951] {standard_task_runner.py:78} INFO - Job 48: Subtask wait_weekly
[2021-01-14 11:51:15,981] {logging_mixin.py:112} INFO - Running %s on host %s <TaskInstance: test_daily_0030.wait_weekly 2021-01-13T00:30:00+00:00 [running]> 1.0.0.127.in-addr.arpa
[2021-01-14 11:51:15,996] {external_task_sensor.py:117} INFO - Poking for test_weekly.None on 2021-01-13T00:30:00+00:00 ... 
[2021-01-14 11:52:05,939] {local_task_job.py:145} WARNING - The recorded hostname 1.0.0.127.in-addr.arpa does not match this instance's hostname iwonjiui-macbookpro.local
[2021-01-14 11:52:05,946] {helpers.py:325} INFO - Sending Signals.SIGTERM to GPID 17399
[2021-01-14 11:52:05,946] {taskinstance.py:955} ERROR - Received SIGTERM. Terminating subprocesses.
[2021-01-14 11:52:05,949] {taskinstance.py:1150} ERROR - Task received SIGTERM signal
Traceback (most recent call last):
  File "/Users/wonji/.pyenv/versions/3.7.7/envs/test_airflow/lib/python3.7/site-packages/airflow/models/taskinstance.py", line 984, in _run_raw_task
    result = task_copy.execute(context=context)
  File "/Users/wonji/.pyenv/versions/3.7.7/envs/test_airflow/lib/python3.7/site-packages/airflow/sensors/base_sensor_operator.py", line 122, in execute
    sleep(self.poke_interval)
  File "/Users/wonji/.pyenv/versions/3.7.7/envs/test_airflow/lib/python3.7/site-packages/airflow/models/taskinstance.py", line 957, in signal_handler
    raise AirflowException("Task received SIGTERM signal")
airflow.exceptions.AirflowException: Task received SIGTERM signal
[2021-01-14 11:52:05,950] {taskinstance.py:1194} INFO - Marking task as UP_FOR_RETRY. dag_id=test_daily_0030, task_id=wait_weekly, execution_date=20210113T003000, start_date=20210114T025115, end_date=20210114T025205
[2021-01-14 11:52:05,961] {configuration.py:373} WARNING - section/key [smtp/smtp_user] not found in config
[2021-01-14 11:52:05,963] {configuration.py:373} WARNING - section/key [smtp/smtp_user] not found in config
[2021-01-14 11:52:05,964] {taskinstance.py:1200} ERROR - Failed to send email to: ['wonji0129@naver.com']
[2021-01-14 11:52:05,964] {taskinstance.py:1201} ERROR - [Errno 61] Connection refused
Traceback (most recent call last):
  File "/Users/wonji/.pyenv/versions/3.7.7/envs/test_airflow/lib/python3.7/site-packages/airflow/models/taskinstance.py", line 984, in _run_raw_task
    result = task_copy.execute(context=context)
  File "/Users/wonji/.pyenv/versions/3.7.7/envs/test_airflow/lib/python3.7/site-packages/airflow/sensors/base_sensor_operator.py", line 122, in execute
    sleep(self.poke_interval)
  File "/Users/wonji/.pyenv/versions/3.7.7/envs/test_airflow/lib/python3.7/site-packages/airflow/models/taskinstance.py", line 957, in signal_handler
    raise AirflowException("Task received SIGTERM signal")
airflow.exceptions.AirflowException: Task received SIGTERM signal

During handling of the above exception, another exception occurred:

Traceback (most recent call last):
  File "/Users/wonji/.pyenv/versions/3.7.7/envs/test_airflow/lib/python3.7/site-packages/airflow/models/taskinstance.py", line 1473, in email_alert
    send_email(self.task.email, subject, html_content)
  File "/Users/wonji/.pyenv/versions/3.7.7/envs/test_airflow/lib/python3.7/site-packages/airflow/utils/email.py", line 62, in send_email
    mime_subtype=mime_subtype, mime_charset=mime_charset, **kwargs)
  File "/Users/wonji/.pyenv/versions/3.7.7/envs/test_airflow/lib/python3.7/site-packages/airflow/utils/email.py", line 108, in send_email_smtp
    send_MIME_email(smtp_mail_from, recipients, msg, dryrun)
  File "/Users/wonji/.pyenv/versions/3.7.7/envs/test_airflow/lib/python3.7/site-packages/airflow/utils/email.py", line 127, in send_MIME_email
    s = smtplib.SMTP_SSL(SMTP_HOST, SMTP_PORT) if SMTP_SSL else smtplib.SMTP(SMTP_HOST, SMTP_PORT)
  File "/Users/wonji/.pyenv/versions/3.7.7/lib/python3.7/smtplib.py", line 251, in __init__
    (code, msg) = self.connect(host, port)
  File "/Users/wonji/.pyenv/versions/3.7.7/lib/python3.7/smtplib.py", line 336, in connect
    self.sock = self._get_socket(host, port, self.timeout)
  File "/Users/wonji/.pyenv/versions/3.7.7/lib/python3.7/smtplib.py", line 307, in _get_socket
    self.source_address)
  File "/Users/wonji/.pyenv/versions/3.7.7/lib/python3.7/socket.py", line 728, in create_connection
    raise err
  File "/Users/wonji/.pyenv/versions/3.7.7/lib/python3.7/socket.py", line 716, in create_connection
    sock.connect(sa)
ConnectionRefusedError: [Errno 61] Connection refused

During handling of the above exception, another exception occurred:

Traceback (most recent call last):
  File "/Users/wonji/.pyenv/versions/3.7.7/envs/test_airflow/lib/python3.7/site-packages/airflow/models/taskinstance.py", line 1198, in handle_failure
    self.email_alert(error)
  File "/Users/wonji/.pyenv/versions/3.7.7/envs/test_airflow/lib/python3.7/site-packages/airflow/models/taskinstance.py", line 1475, in email_alert
    send_email(self.task.email, subject, html_content_err)
  File "/Users/wonji/.pyenv/versions/3.7.7/envs/test_airflow/lib/python3.7/site-packages/airflow/utils/email.py", line 62, in send_email
    mime_subtype=mime_subtype, mime_charset=mime_charset, **kwargs)
  File "/Users/wonji/.pyenv/versions/3.7.7/envs/test_airflow/lib/python3.7/site-packages/airflow/utils/email.py", line 108, in send_email_smtp
    send_MIME_email(smtp_mail_from, recipients, msg, dryrun)
  File "/Users/wonji/.pyenv/versions/3.7.7/envs/test_airflow/lib/python3.7/site-packages/airflow/utils/email.py", line 127, in send_MIME_email
    s = smtplib.SMTP_SSL(SMTP_HOST, SMTP_PORT) if SMTP_SSL else smtplib.SMTP(SMTP_HOST, SMTP_PORT)
  File "/Users/wonji/.pyenv/versions/3.7.7/lib/python3.7/smtplib.py", line 251, in __init__
    (code, msg) = self.connect(host, port)
  File "/Users/wonji/.pyenv/versions/3.7.7/lib/python3.7/smtplib.py", line 336, in connect
    self.sock = self._get_socket(host, port, self.timeout)
  File "/Users/wonji/.pyenv/versions/3.7.7/lib/python3.7/smtplib.py", line 307, in _get_socket
    self.source_address)
  File "/Users/wonji/.pyenv/versions/3.7.7/lib/python3.7/socket.py", line 728, in create_connection
    raise err
  File "/Users/wonji/.pyenv/versions/3.7.7/lib/python3.7/socket.py", line 716, in create_connection
    sock.connect(sa)
ConnectionRefusedError: [Errno 61] Connection refused
[2021-01-14 11:52:05,977] {helpers.py:291} INFO - Process psutil.Process(pid=17399, status='terminated', exitcode=1, started='11:51:15') (17399) terminated with exit code 1
