[2021-01-14 10:58:32,094] {taskinstance.py:670} INFO - Dependencies all met for <TaskInstance: test_daily_0030.wait_daily 2021-01-06T00:30:00+00:00 [queued]>
[2021-01-14 10:58:32,105] {taskinstance.py:670} INFO - Dependencies all met for <TaskInstance: test_daily_0030.wait_daily 2021-01-06T00:30:00+00:00 [queued]>
[2021-01-14 10:58:32,105] {taskinstance.py:880} INFO - 
--------------------------------------------------------------------------------
[2021-01-14 10:58:32,105] {taskinstance.py:881} INFO - Starting attempt 1 of 4
[2021-01-14 10:58:32,105] {taskinstance.py:882} INFO - 
--------------------------------------------------------------------------------
[2021-01-14 10:58:32,111] {taskinstance.py:901} INFO - Executing <Task(ExternalTaskSensor): wait_daily> on 2021-01-06T00:30:00+00:00
[2021-01-14 10:58:32,115] {standard_task_runner.py:54} INFO - Started process 11935 to run task
[2021-01-14 10:58:32,137] {standard_task_runner.py:77} INFO - Running: ['airflow', 'run', 'test_daily_0030', 'wait_daily', '2021-01-06T00:30:00+00:00', '--job_id', '6', '--pool', 'default_pool', '--raw', '-sd', 'DAGS_FOLDER/test_daily_0030.py', '--cfg_path', '/var/folders/1c/xhkpty0142l7xwkrqtm3t9p80000gn/T/tmpufpl4a40']
[2021-01-14 10:58:32,138] {standard_task_runner.py:78} INFO - Job 6: Subtask wait_daily
[2021-01-14 10:58:32,171] {logging_mixin.py:112} INFO - Running %s on host %s <TaskInstance: test_daily_0030.wait_daily 2021-01-06T00:30:00+00:00 [running]> 1.0.0.127.in-addr.arpa
[2021-01-14 10:58:32,187] {external_task_sensor.py:117} INFO - Poking for test_daily_0015.None on 2021-01-06T00:30:00+00:00 ... 
[2021-01-14 10:58:32,193] {taskinstance.py:1150} ERROR - The external DAG test_daily_0015 does not exist.
Traceback (most recent call last):
  File "/Users/wonji/.pyenv/versions/3.7.7/envs/test_airflow/lib/python3.7/site-packages/airflow/models/taskinstance.py", line 984, in _run_raw_task
    result = task_copy.execute(context=context)
  File "/Users/wonji/.pyenv/versions/3.7.7/envs/test_airflow/lib/python3.7/site-packages/airflow/sensors/base_sensor_operator.py", line 107, in execute
    while not self.poke(context):
  File "/Users/wonji/.pyenv/versions/3.7.7/envs/test_airflow/lib/python3.7/site-packages/airflow/utils/db.py", line 74, in wrapper
    return func(*args, **kwargs)
  File "/Users/wonji/.pyenv/versions/3.7.7/envs/test_airflow/lib/python3.7/site-packages/airflow/sensors/external_task_sensor.py", line 130, in poke
    '{} does not exist.'.format(self.external_dag_id))
airflow.exceptions.AirflowException: The external DAG test_daily_0015 does not exist.
[2021-01-14 10:58:32,198] {taskinstance.py:1194} INFO - Marking task as UP_FOR_RETRY. dag_id=test_daily_0030, task_id=wait_daily, execution_date=20210106T003000, start_date=20210114T015832, end_date=20210114T015832
[2021-01-14 10:58:32,209] {configuration.py:373} WARNING - section/key [smtp/smtp_user] not found in config
[2021-01-14 10:58:32,211] {configuration.py:373} WARNING - section/key [smtp/smtp_user] not found in config
[2021-01-14 10:58:32,212] {taskinstance.py:1200} ERROR - Failed to send email to: ['wonji']
[2021-01-14 10:58:32,212] {taskinstance.py:1201} ERROR - [Errno 61] Connection refused
Traceback (most recent call last):
  File "/Users/wonji/.pyenv/versions/3.7.7/envs/test_airflow/lib/python3.7/site-packages/airflow/models/taskinstance.py", line 984, in _run_raw_task
    result = task_copy.execute(context=context)
  File "/Users/wonji/.pyenv/versions/3.7.7/envs/test_airflow/lib/python3.7/site-packages/airflow/sensors/base_sensor_operator.py", line 107, in execute
    while not self.poke(context):
  File "/Users/wonji/.pyenv/versions/3.7.7/envs/test_airflow/lib/python3.7/site-packages/airflow/utils/db.py", line 74, in wrapper
    return func(*args, **kwargs)
  File "/Users/wonji/.pyenv/versions/3.7.7/envs/test_airflow/lib/python3.7/site-packages/airflow/sensors/external_task_sensor.py", line 130, in poke
    '{} does not exist.'.format(self.external_dag_id))
airflow.exceptions.AirflowException: The external DAG test_daily_0015 does not exist.

During handling of the above exception, another exception occurred:

Traceback (most recent call last):
  File "/Users/wonji/.pyenv/versions/3.7.7/envs/test_airflow/lib/python3.7/site-packages/airflow/models/taskinstance.py", line 1473, in email_alert
    send_email(self.task.email, subject, html_content)
  File "/Users/wonji/.pyenv/versions/3.7.7/envs/test_airflow/lib/python3.7/site-packages/airflow/utils/email.py", line 62, in send_email
    mime_subtype=mime_subtype, mime_charset=mime_charset, **kwargs)
  File "/Users/wonji/.pyenv/versions/3.7.7/envs/test_airflow/lib/python3.7/site-packages/airflow/utils/email.py", line 108, in send_email_smtp
    send_MIME_email(smtp_mail_from, recipients, msg, dryrun)
  File "/Users/wonji/.pyenv/versions/3.7.7/envs/test_airflow/lib/python3.7/site-packages/airflow/utils/email.py", line 127, in send_MIME_email
    s = smtplib.SMTP_SSL(SMTP_HOST, SMTP_PORT) if SMTP_SSL else smtplib.SMTP(SMTP_HOST, SMTP_PORT)
  File "/Users/wonji/.pyenv/versions/3.7.7/lib/python3.7/smtplib.py", line 251, in __init__
    (code, msg) = self.connect(host, port)
  File "/Users/wonji/.pyenv/versions/3.7.7/lib/python3.7/smtplib.py", line 336, in connect
    self.sock = self._get_socket(host, port, self.timeout)
  File "/Users/wonji/.pyenv/versions/3.7.7/lib/python3.7/smtplib.py", line 307, in _get_socket
    self.source_address)
  File "/Users/wonji/.pyenv/versions/3.7.7/lib/python3.7/socket.py", line 728, in create_connection
    raise err
  File "/Users/wonji/.pyenv/versions/3.7.7/lib/python3.7/socket.py", line 716, in create_connection
    sock.connect(sa)
ConnectionRefusedError: [Errno 61] Connection refused

During handling of the above exception, another exception occurred:

Traceback (most recent call last):
  File "/Users/wonji/.pyenv/versions/3.7.7/envs/test_airflow/lib/python3.7/site-packages/airflow/models/taskinstance.py", line 1198, in handle_failure
    self.email_alert(error)
  File "/Users/wonji/.pyenv/versions/3.7.7/envs/test_airflow/lib/python3.7/site-packages/airflow/models/taskinstance.py", line 1475, in email_alert
    send_email(self.task.email, subject, html_content_err)
  File "/Users/wonji/.pyenv/versions/3.7.7/envs/test_airflow/lib/python3.7/site-packages/airflow/utils/email.py", line 62, in send_email
    mime_subtype=mime_subtype, mime_charset=mime_charset, **kwargs)
  File "/Users/wonji/.pyenv/versions/3.7.7/envs/test_airflow/lib/python3.7/site-packages/airflow/utils/email.py", line 108, in send_email_smtp
    send_MIME_email(smtp_mail_from, recipients, msg, dryrun)
  File "/Users/wonji/.pyenv/versions/3.7.7/envs/test_airflow/lib/python3.7/site-packages/airflow/utils/email.py", line 127, in send_MIME_email
    s = smtplib.SMTP_SSL(SMTP_HOST, SMTP_PORT) if SMTP_SSL else smtplib.SMTP(SMTP_HOST, SMTP_PORT)
  File "/Users/wonji/.pyenv/versions/3.7.7/lib/python3.7/smtplib.py", line 251, in __init__
    (code, msg) = self.connect(host, port)
  File "/Users/wonji/.pyenv/versions/3.7.7/lib/python3.7/smtplib.py", line 336, in connect
    self.sock = self._get_socket(host, port, self.timeout)
  File "/Users/wonji/.pyenv/versions/3.7.7/lib/python3.7/smtplib.py", line 307, in _get_socket
    self.source_address)
  File "/Users/wonji/.pyenv/versions/3.7.7/lib/python3.7/socket.py", line 728, in create_connection
    raise err
  File "/Users/wonji/.pyenv/versions/3.7.7/lib/python3.7/socket.py", line 716, in create_connection
    sock.connect(sa)
ConnectionRefusedError: [Errno 61] Connection refused
[2021-01-14 10:58:37,090] {local_task_job.py:102} INFO - Task exited with return code 1
